async_dict.py, async_dict.fp_int_key_access_ok, 1, PULSE_UNAWAITED_AWAITABLE, no_bucket, ERROR, [allocation part of the trace starts here,allocated by async call here,awaitable becomes unreachable here]
async_dict.py, async_dict.int_key_access_bad, 1, PULSE_UNAWAITED_AWAITABLE, no_bucket, ERROR, [allocation part of the trace starts here,allocated by async call here,awaitable becomes unreachable here]
async_dict.py, async_dict.str_key_access_bad, 2, PULSE_UNAWAITED_AWAITABLE, no_bucket, ERROR, [allocation part of the trace starts here,allocated by async call here,awaitable becomes unreachable here]
async_global.py, async_global.__module_body__, 24, PULSE_UNAWAITED_AWAITABLE, no_bucket, ERROR, [allocation part of the trace starts here,parameter `globals` of async_global.__module_body__,assigned,when calling `Closure[async_global.set_unwaited_global].call` here,parameter `__this` of Closure[async_global.set_unwaited_global].call,when calling `async_global.set_unwaited_global` here,allocated by async call here,awaitable becomes unreachable here]
async_import_simple.py, async_import_simple.with_import_bad, 1, PULSE_UNAWAITED_AWAITABLE, no_bucket, ERROR, [allocation part of the trace starts here,allocated by async call here,awaitable becomes unreachable here]
async_import_simple.py, async_import_simple.with_from_import_bad, 1, PULSE_UNAWAITED_AWAITABLE, no_bucket, ERROR, [allocation part of the trace starts here,allocated by async call here,awaitable becomes unreachable here]
async_import_simple.py, async_import_simple.with_imported_class_bad, 1, PULSE_UNAWAITED_AWAITABLE, no_bucket, ERROR, [allocation part of the trace starts here,allocated by async call here,awaitable becomes unreachable here]
async_import_with_package.py, async_import_with_package.bad1, 1, PULSE_UNAWAITED_AWAITABLE, no_bucket, ERROR, [allocation part of the trace starts here,allocated by async call here,awaitable becomes unreachable here]
async_import_with_package.py, async_import_with_package.bad2, 1, PULSE_UNAWAITED_AWAITABLE, no_bucket, ERROR, [allocation part of the trace starts here,allocated by async call here,awaitable becomes unreachable here]
async_import_with_package.py, async_import_with_package.bad3, 1, PULSE_UNAWAITED_AWAITABLE, no_bucket, ERROR, [allocation part of the trace starts here,allocated by async call here,awaitable becomes unreachable here]
async_import_with_package.py, async_import_with_package.from_class_bad3, 1, PULSE_UNAWAITED_AWAITABLE, no_bucket, ERROR, [allocation part of the trace starts here,allocated by async call here,awaitable becomes unreachable here]
async_import_with_package.py, async_import_with_package.bad4, 1, PULSE_UNAWAITED_AWAITABLE, no_bucket, ERROR, [allocation part of the trace starts here,allocated by async call here,awaitable becomes unreachable here]
async_import_with_package.py, async_import_with_package.bad5, 1, PULSE_UNAWAITED_AWAITABLE, no_bucket, ERROR, [allocation part of the trace starts here,allocated by async call here,awaitable becomes unreachable here]
async_import_with_package.py, async_import_with_package.bad6, 1, PULSE_UNAWAITED_AWAITABLE, no_bucket, ERROR, [allocation part of the trace starts here,allocated by async call here,awaitable becomes unreachable here]
async_lambda.py, async_lambda.lambda_bad, 2, PULSE_UNAWAITED_AWAITABLE, no_bucket, ERROR, [allocation part of the trace starts here,when calling `Closure[async_lambda.lambda_bad._$lambda].call` here,when calling `async_lambda.lambda_bad::_$lambda` here,allocated by async call here,awaitable becomes unreachable here]
async_lambda.py, async_lambda.lambda_param_bad, 1, PULSE_UNAWAITED_AWAITABLE, no_bucket, ERROR, [allocation part of the trace starts here,when calling `Closure[async_lambda._$lambda].call` here,when calling `async_lambda._$lambda` here,allocated by async call here,awaitable becomes unreachable here]
async_lambda.py, async_lambda.lambda_param_bad, 1, PULSE_UNAWAITED_AWAITABLE, no_bucket, ERROR, [allocation part of the trace starts here,when calling `Closure[async_lambda.lambda_param_bad_call_bad._$lambda].call` here,when calling `async_lambda.lambda_param_bad_call_bad::_$lambda` here,allocated by async call here,awaitable becomes unreachable here]
async_lambda.py, async_lambda.lambda_param_bad_call_bad, 1, PULSE_UNAWAITED_AWAITABLE, no_bucket, ERROR, [allocation part of the trace starts here,allocated by async call here,awaitable becomes unreachable here]
async_lambda.py, async_lambda.__module_body__, 30, PULSE_UNAWAITED_AWAITABLE, no_bucket, ERROR, [allocation part of the trace starts here,allocated by async call here,awaitable becomes unreachable here]
async_level0.py, async_level0.sleep_bad, 1, PULSE_UNAWAITED_AWAITABLE, no_bucket, ERROR, [allocation part of the trace starts here,allocated by async call here,awaitable becomes unreachable here]
async_level0.py, async_level0.call_sleep_bad, 1, PULSE_UNAWAITED_AWAITABLE, no_bucket, ERROR, [allocation part of the trace starts here,allocated by async call here,awaitable becomes unreachable here]
async_level0.py, async_level0.call_sleep_with_branchs_bad1, 3, PULSE_UNAWAITED_AWAITABLE, no_bucket, ERROR, [allocation part of the trace starts here,allocated by async call here,awaitable becomes unreachable here]
async_level0.py, async_level0.call_sleep_with_branchs_bad2, 4, PULSE_UNAWAITED_AWAITABLE, no_bucket, ERROR, [allocation part of the trace starts here,allocated by async call here,awaitable becomes unreachable here]
async_level0.py, async_level0.tuple0_bad, 2, PULSE_UNAWAITED_AWAITABLE, no_bucket, ERROR, [allocation part of the trace starts here,allocated by async call here,awaitable becomes unreachable here]
async_level0.py, async_level0.tuple1_bad, 2, PULSE_UNAWAITED_AWAITABLE, no_bucket, ERROR, [allocation part of the trace starts here,allocated by async call here,awaitable becomes unreachable here]
async_level0.py, async_level0.with_str_bad, 2, PULSE_UNAWAITED_AWAITABLE, no_bucket, ERROR, [allocation part of the trace starts here,allocated by async call here,awaitable becomes unreachable here]
async_level0.py, async_level0.call_fst_bad, 1, PULSE_UNAWAITED_AWAITABLE, no_bucket, ERROR, [allocation part of the trace starts here,allocated by async call here,awaitable becomes unreachable here]
async_level0.py, async_level0.compare_lt_bad, 3, PULSE_UNAWAITED_AWAITABLE, no_bucket, ERROR, [allocation part of the trace starts here,allocated by async call here,awaitable becomes unreachable here]
async_level0.py, async_level0.compare_gt_bad, 3, PULSE_UNAWAITED_AWAITABLE, no_bucket, ERROR, [allocation part of the trace starts here,allocated by async call here,awaitable becomes unreachable here]
async_level0.py, async_level0.use_py_bool_bad, 2, PULSE_UNAWAITED_AWAITABLE, no_bucket, ERROR, [allocation part of the trace starts here,allocated by async call here,awaitable becomes unreachable here]
async_level0.py, async_level0.use_py_get_iter_bad, 2, PULSE_UNAWAITED_AWAITABLE, no_bucket, ERROR, [allocation part of the trace starts here,allocated by async call here,awaitable becomes unreachable here]
async_level1.py, async_level1.D::main, 1, PULSE_UNAWAITED_AWAITABLE, no_bucket, ERROR, [allocation part of the trace starts here,allocated by async call here,awaitable becomes unreachable here]
async_level1.py, async_level1.instantiate_D_bad, 1, PULSE_UNAWAITED_AWAITABLE, no_bucket, ERROR, [allocation part of the trace starts here,when calling `Closure[async_level1.D.__init__].call` here,when calling `async_level1.D::__init__` here,allocated by async call here,awaitable becomes unreachable here]
async_typing.py, async_typing.await_condition_typing_int_bad, 4, PULSE_UNAWAITED_AWAITABLE, no_bucket, ERROR, [allocation part of the trace starts here,allocated by async call here,awaitable becomes unreachable here]
async_typing.py, async_typing.await_condition_typing_with_arg_bad, 4, PULSE_UNAWAITED_AWAITABLE, no_bucket, ERROR, [allocation part of the trace starts here,allocated by async call here,awaitable becomes unreachable here]
async_typing.py, async_typing.fp_await_condition_typing_user_defined_ok, 5, PULSE_UNAWAITED_AWAITABLE, no_bucket, ERROR, [allocation part of the trace starts here,allocated by async call here,awaitable becomes unreachable here]
async_typing.py, async_typing.fp_await_condition_typing_fun_ok, 7, PULSE_UNAWAITED_AWAITABLE, no_bucket, ERROR, [allocation part of the trace starts here,allocated by async call here,awaitable becomes unreachable here]
async_typing.py, async_typing.await_condition_is_none_bad, 3, PULSE_UNAWAITED_AWAITABLE, no_bucket, ERROR, [allocation part of the trace starts here,allocated by async call here,awaitable becomes unreachable here]
async_typing.py, async_typing.await_condition_bool_none_bad, 5, PULSE_UNAWAITED_AWAITABLE, no_bucket, ERROR, [allocation part of the trace starts here,allocated by async call here,awaitable becomes unreachable here]
async_typing.py, async_typing.fp_await_condition_val_equal_ok, 6, PULSE_UNAWAITED_AWAITABLE, no_bucket, ERROR, [allocation part of the trace starts here,allocated by async call here,awaitable becomes unreachable here]
async_typing.py, async_typing.await_condition_phys_equal_bad, 6, PULSE_UNAWAITED_AWAITABLE, no_bucket, ERROR, [allocation part of the trace starts here,allocated by async call here,awaitable becomes unreachable here]
builtins.py, builtins.fp_dict_comp_ok, 1, PULSE_UNAWAITED_AWAITABLE, no_bucket, ERROR, [allocation part of the trace starts here,allocated by async call here,awaitable becomes unreachable here]
cyclic_import.py, cyclic_import.__module_body__, 5, MUTUAL_RECURSION_CYCLE, no_bucket, WARNING, [`cyclic_import.__module_body__` makes a recursive call to `cyclic_import.__module_body__`]
dict_import.py, dict_import.read_class_companion_property_with_import_bad, 2, PULSE_DICT_MISSING_KEY, no_bucket, ERROR, [allocated by call to `new` (modelled),read to uninitialized value occurs here]
dict_import.py, dict_import.instance_attribute_from_class_companion_with_import_bad, 3, PULSE_DICT_MISSING_KEY, no_bucket, ERROR, [allocated by call to `new` (modelled),read to uninitialized value occurs here]
dict_import.py, dict_import.instance_attribute_with_import_bad, 3, PULSE_DICT_MISSING_KEY, no_bucket, ERROR, [allocated by call to `new` (modelled),read to uninitialized value occurs here]
dict_import.py, dict_import.read_class_companion_property_with_import_from_bad, 2, PULSE_DICT_MISSING_KEY, no_bucket, ERROR, [allocated by call to `new` (modelled),read to uninitialized value occurs here]
dict_import.py, dict_import.instance_attribute_from_class_companion_with_import_from_bad, 3, PULSE_DICT_MISSING_KEY, no_bucket, ERROR, [allocated by call to `new` (modelled),read to uninitialized value occurs here]
dict_import.py, dict_import.instance_attribute_with_import_from_bad, 3, PULSE_DICT_MISSING_KEY, no_bucket, ERROR, [allocated by call to `new` (modelled),read to uninitialized value occurs here]
dict_level0.py, dict_level0.dict_missing_key_const_str_bad, 2, PULSE_DICT_MISSING_KEY, no_bucket, ERROR, [allocated by call to `new` (modelled),read to uninitialized value occurs here]
dict_level0.py, dict_level0.dict_missing_key_const_str_with_int_key_bad, 2, PULSE_DICT_MISSING_KEY, no_bucket, ERROR, [allocated by call to `new` (modelled),read to uninitialized value occurs here]
dict_level0.py, dict_level0.dict_missing_key_const_str_store_int_key_bad, 3, PULSE_DICT_MISSING_KEY, no_bucket, ERROR, [allocated by call to `new` (modelled),read to uninitialized value occurs here]
dict_level0.py, dict_level0.dict_access_fun_call_bad, 2, PULSE_DICT_MISSING_KEY, no_bucket, ERROR, [in call to `Closure[dict_level0.get_dict].call`,in call to `dict_level0.get_dict`,allocated by call to `new` (modelled),returned,return from call to `dict_level0.get_dict`,returned,return from call to `Closure[dict_level0.get_dict].call`,read to uninitialized value occurs here]
dict_level0.py, dict_level0.dict_missing_key_dict_builtin_const_map_bad, 2, PULSE_DICT_MISSING_KEY, no_bucket, ERROR, [allocated by call to `new` (modelled),read to uninitialized value occurs here]
dict_level0.py, dict_level0.dict_missing_key_builtin_empty_bad, 2, PULSE_DICT_MISSING_KEY, no_bucket, ERROR, [allocated by call to `new` (modelled),read to uninitialized value occurs here]
dict_level0.py, dict_level0.dict_missing_str_key_in_op_bad, 3, PULSE_DICT_MISSING_KEY, no_bucket, ERROR, [allocated by call to `new` (modelled),read to uninitialized value occurs here]
dict_level0.py, dict_level0.fp_dict_missing_int_key_in_op_ok, 3, PULSE_DICT_MISSING_KEY, no_bucket, ERROR, [allocated by call to `new` (modelled),read to uninitialized value occurs here]
dict_level0.py, dict_level0.DictField::get_key_bad, 2, PULSE_DICT_MISSING_KEY, no_bucket, ERROR, [allocated by call to `new` (modelled),read to uninitialized value occurs here]
dict_level0.py, dict_level0.read_class_companion_property_bad, 2, PULSE_DICT_MISSING_KEY, no_bucket, ERROR, [allocated by call to `new` (modelled),read to uninitialized value occurs here]
dict_level0.py, dict_level0.instance_attribute_from_class_companion_bad, 3, PULSE_DICT_MISSING_KEY, no_bucket, ERROR, [allocated by call to `new` (modelled),read to uninitialized value occurs here]
dict_level0.py, dict_level0.instance_attribute_bad, 3, PULSE_DICT_MISSING_KEY, no_bucket, ERROR, [allocated by call to `new` (modelled),read to uninitialized value occurs here]
dict_object_oriented.py, dict_object_oriented.set_attribute_with_init_bad, 3, PULSE_DICT_MISSING_KEY, no_bucket, ERROR, [allocated by call to `new` (modelled),read to uninitialized value occurs here]
dict_object_oriented.py, dict_object_oriented.set_attribute_with_init_read_with_getter_bad, 3, PULSE_DICT_MISSING_KEY, no_bucket, ERROR, [allocated by call to `new` (modelled),read to uninitialized value occurs here]
