async_global.py, async_global.__module_body__, 24, PULSE_UNAWAITED_AWAITABLE, no_bucket, ERROR, [allocation part of the trace starts here,parameter `globals` of async_global.__module_body__,assigned,when calling `closure:async_global:0.call` here,parameter `__this` of closure:async_global:0.call,when calling `async_global.set_unwaited_global` here,allocated by async call here,awaitable becomes unreachable here]
async_import_simple.py, async_import_simple.with_import_bad, 1, PULSE_UNAWAITED_AWAITABLE, no_bucket, ERROR, [allocation part of the trace starts here,allocated by async call here,awaitable becomes unreachable here]
async_import_simple.py, async_import_simple.with_from_import_bad, 1, PULSE_UNAWAITED_AWAITABLE, no_bucket, ERROR, [allocation part of the trace starts here,allocated by async call here,awaitable becomes unreachable here]
async_import_simple.py, async_import_simple.with_imported_class_bad, 1, PULSE_UNAWAITED_AWAITABLE, no_bucket, ERROR, [allocation part of the trace starts here,allocated by async call here,awaitable becomes unreachable here]
async_import_with_package.py, async_import_with_package.bad1, 1, PULSE_UNAWAITED_AWAITABLE, no_bucket, ERROR, [allocation part of the trace starts here,allocated by async call here,awaitable becomes unreachable here]
async_import_with_package.py, async_import_with_package.bad2, 1, PULSE_UNAWAITED_AWAITABLE, no_bucket, ERROR, [allocation part of the trace starts here,allocated by async call here,awaitable becomes unreachable here]
async_import_with_package.py, async_import_with_package.bad3, 1, PULSE_UNAWAITED_AWAITABLE, no_bucket, ERROR, [allocation part of the trace starts here,allocated by async call here,awaitable becomes unreachable here]
async_import_with_package.py, async_import_with_package.from_class_bad3, 1, PULSE_UNAWAITED_AWAITABLE, no_bucket, ERROR, [allocation part of the trace starts here,allocated by async call here,awaitable becomes unreachable here]
async_import_with_package.py, async_import_with_package.bad4, 1, PULSE_UNAWAITED_AWAITABLE, no_bucket, ERROR, [allocation part of the trace starts here,allocated by async call here,awaitable becomes unreachable here]
async_import_with_package.py, async_import_with_package.bad5, 1, PULSE_UNAWAITED_AWAITABLE, no_bucket, ERROR, [allocation part of the trace starts here,allocated by async call here,awaitable becomes unreachable here]
async_import_with_package.py, async_import_with_package.bad6, 1, PULSE_UNAWAITED_AWAITABLE, no_bucket, ERROR, [allocation part of the trace starts here,allocated by async call here,awaitable becomes unreachable here]
async_lambda.py, async_lambda.lambda_bad, 2, PULSE_UNAWAITED_AWAITABLE, no_bucket, ERROR, [allocation part of the trace starts here,when calling `closure:async_lambda:6.call` here,when calling `async_lambda.lambda_bad::_$lambda` here,allocated by async call here,awaitable becomes unreachable here]
async_lambda.py, async_lambda.lambda_param_bad, 1, PULSE_UNAWAITED_AWAITABLE, no_bucket, ERROR, [allocation part of the trace starts here,when calling `closure:async_lambda:5.call` here,when calling `async_lambda._$lambda` here,allocated by async call here,awaitable becomes unreachable here]
async_lambda.py, async_lambda.lambda_param_bad, 1, PULSE_UNAWAITED_AWAITABLE, no_bucket, ERROR, [allocation part of the trace starts here,when calling `closure:async_lambda:8.call` here,when calling `async_lambda.lambda_param_bad_call_bad::_$lambda` here,allocated by async call here,awaitable becomes unreachable here]
async_lambda.py, async_lambda.lambda_param_bad_call_bad, 1, PULSE_UNAWAITED_AWAITABLE, no_bucket, ERROR, [allocation part of the trace starts here,allocated by async call here,awaitable becomes unreachable here]
async_lambda.py, async_lambda.__module_body__, 30, PULSE_UNAWAITED_AWAITABLE, no_bucket, ERROR, [allocation part of the trace starts here,allocated by async call here,awaitable becomes unreachable here]
async_level0.py, async_level0.sleep_bad, 1, PULSE_UNAWAITED_AWAITABLE, no_bucket, ERROR, [allocation part of the trace starts here,allocated by async call here,awaitable becomes unreachable here]
async_level0.py, async_level0.call_sleep_bad, 1, PULSE_UNAWAITED_AWAITABLE, no_bucket, ERROR, [allocation part of the trace starts here,allocated by async call here,awaitable becomes unreachable here]
async_level0.py, async_level0.call_sleep_with_branchs_bad1, 3, PULSE_UNAWAITED_AWAITABLE, no_bucket, ERROR, [allocation part of the trace starts here,allocated by async call here,awaitable becomes unreachable here]
async_level0.py, async_level0.call_sleep_with_branchs_bad2, 4, PULSE_UNAWAITED_AWAITABLE, no_bucket, ERROR, [allocation part of the trace starts here,allocated by async call here,awaitable becomes unreachable here]
async_level0.py, async_level0.tuple0_bad, 2, PULSE_UNAWAITED_AWAITABLE, no_bucket, ERROR, [allocation part of the trace starts here,allocated by async call here,awaitable becomes unreachable here]
async_level0.py, async_level0.tuple1_bad, 2, PULSE_UNAWAITED_AWAITABLE, no_bucket, ERROR, [allocation part of the trace starts here,allocated by async call here,awaitable becomes unreachable here]
async_level0.py, async_level0.with_str_bad, 2, PULSE_UNAWAITED_AWAITABLE, no_bucket, ERROR, [allocation part of the trace starts here,allocated by async call here,awaitable becomes unreachable here]
async_level0.py, async_level0.call_fst_bad, 1, PULSE_UNAWAITED_AWAITABLE, no_bucket, ERROR, [allocation part of the trace starts here,allocated by async call here,awaitable becomes unreachable here]
async_level1.py, async_level1.D::main, 1, PULSE_UNAWAITED_AWAITABLE, no_bucket, ERROR, [allocation part of the trace starts here,allocated by async call here,awaitable becomes unreachable here]
async_typing.py, async_typing.await_condition_typing_bad, 4, PULSE_UNAWAITED_AWAITABLE, no_bucket, ERROR, [allocation part of the trace starts here,allocated by async call here,awaitable becomes unreachable here]
async_typing.py, async_typing.await_condition_typing_with_arg_bad, 4, PULSE_UNAWAITED_AWAITABLE, no_bucket, ERROR, [allocation part of the trace starts here,allocated by async call here,awaitable becomes unreachable here]
async_typing.py, async_typing.fp_await_condition_typing_user_defined_ok, 5, PULSE_UNAWAITED_AWAITABLE, no_bucket, ERROR, [allocation part of the trace starts here,allocated by async call here,awaitable becomes unreachable here]
async_typing.py, async_typing.fp_await_condition_typing_fun_ok, 7, PULSE_UNAWAITED_AWAITABLE, no_bucket, ERROR, [allocation part of the trace starts here,allocated by async call here,awaitable becomes unreachable here]
async_typing.py, async_typing.fp_await_condition_val_equal_ok, 6, PULSE_UNAWAITED_AWAITABLE, no_bucket, ERROR, [allocation part of the trace starts here,allocated by async call here,awaitable becomes unreachable here]
async_typing.py, async_typing.await_condition_phys_equal_bad, 6, PULSE_UNAWAITED_AWAITABLE, no_bucket, ERROR, [allocation part of the trace starts here,allocated by async call here,awaitable becomes unreachable here]
