async_global.py, async_global.__module_body__, 24, PULSE_UNAWAITED_AWAITABLE, no_bucket, ERROR, [allocation part of the trace starts here,parameter `globals` of async_global.__module_body__,assigned,when calling `closure:async_global:0.call` here,parameter `__this` of closure:async_global:0.call,when calling `async_global.set_unwaited_global` here,allocated by async call here,awaitable becomes unreachable here]
async_import_simple.py, async_import_simple.with_import_bad, 1, PULSE_UNAWAITED_AWAITABLE, no_bucket, ERROR, [allocation part of the trace starts here,allocated by async call here,awaitable becomes unreachable here]
async_import_simple.py, async_import_simple.with_from_import_bad, 1, PULSE_UNAWAITED_AWAITABLE, no_bucket, ERROR, [allocation part of the trace starts here,allocated by async call here,awaitable becomes unreachable here]
async_import_simple.py, async_import_simple.with_imported_class_bad, 1, PULSE_UNAWAITED_AWAITABLE, no_bucket, ERROR, [allocation part of the trace starts here,allocated by async call here,awaitable becomes unreachable here]
async_import_with_package.py, async_import_with_package.bad1, 1, PULSE_UNAWAITED_AWAITABLE, no_bucket, ERROR, [allocation part of the trace starts here,allocated by async call here,awaitable becomes unreachable here]
async_import_with_package.py, async_import_with_package.bad2, 1, PULSE_UNAWAITED_AWAITABLE, no_bucket, ERROR, [allocation part of the trace starts here,allocated by async call here,awaitable becomes unreachable here]
async_import_with_package.py, async_import_with_package.bad3, 1, PULSE_UNAWAITED_AWAITABLE, no_bucket, ERROR, [allocation part of the trace starts here,allocated by async call here,awaitable becomes unreachable here]
async_import_with_package.py, async_import_with_package.from_class_bad3, 1, PULSE_UNAWAITED_AWAITABLE, no_bucket, ERROR, [allocation part of the trace starts here,allocated by async call here,awaitable becomes unreachable here]
async_import_with_package.py, async_import_with_package.bad4, 1, PULSE_UNAWAITED_AWAITABLE, no_bucket, ERROR, [allocation part of the trace starts here,allocated by async call here,awaitable becomes unreachable here]
async_import_with_package.py, async_import_with_package.bad5, 1, PULSE_UNAWAITED_AWAITABLE, no_bucket, ERROR, [allocation part of the trace starts here,allocated by async call here,awaitable becomes unreachable here]
async_import_with_package.py, async_import_with_package.bad6, 1, PULSE_UNAWAITED_AWAITABLE, no_bucket, ERROR, [allocation part of the trace starts here,allocated by async call here,awaitable becomes unreachable here]
async_level0.py, async_level0.sleep_bad, 1, PULSE_UNAWAITED_AWAITABLE, no_bucket, ERROR, [allocation part of the trace starts here,allocated by async call here,awaitable becomes unreachable here]
async_level0.py, async_level0.call_sleep_bad, 1, PULSE_UNAWAITED_AWAITABLE, no_bucket, ERROR, [allocation part of the trace starts here,allocated by async call here,awaitable becomes unreachable here]
async_level0.py, async_level0.call_sleep_with_branchs_bad1, 3, PULSE_UNAWAITED_AWAITABLE, no_bucket, ERROR, [allocation part of the trace starts here,allocated by async call here,awaitable becomes unreachable here]
async_level0.py, async_level0.call_sleep_with_branchs_bad2, 4, PULSE_UNAWAITED_AWAITABLE, no_bucket, ERROR, [allocation part of the trace starts here,allocated by async call here,awaitable becomes unreachable here]
async_level0.py, async_level0.tuple0_bad, 2, PULSE_UNAWAITED_AWAITABLE, no_bucket, ERROR, [allocation part of the trace starts here,allocated by async call here,awaitable becomes unreachable here]
async_level0.py, async_level0.tuple1_bad, 2, PULSE_UNAWAITED_AWAITABLE, no_bucket, ERROR, [allocation part of the trace starts here,allocated by async call here,awaitable becomes unreachable here]
async_level0.py, async_level0.call_fst_bad, 1, PULSE_UNAWAITED_AWAITABLE, no_bucket, ERROR, [allocation part of the trace starts here,allocated by async call here,awaitable becomes unreachable here]
async_level1.py, async_level1.D::main, 1, PULSE_UNAWAITED_AWAITABLE, no_bucket, ERROR, [allocation part of the trace starts here,allocated by async call here,awaitable becomes unreachable here]
